{"tag": "function", "depth": 1, "time": "2020-11-03 00:23:45", "data": {"name": "shell", "call_args": {"cmd": "adb shell pm list packages -s"}, "start_time": 1604334225.247905, "traceback": "Traceback (most recent call last):\n  File \"C:\\Users\\\u738b\u4ed4\u6770\\AppData\\Local\\Programs\\Python\\Python36\\lib\\site-packages\\airtest\\core\\android\\adb.py\", line 368, in shell\n    out = self.raw_shell(cmd)\n  File \"C:\\Users\\\u738b\u4ed4\u6770\\AppData\\Local\\Programs\\Python\\Python36\\lib\\site-packages\\airtest\\core\\android\\adb.py\", line 326, in raw_shell\n    out = self.cmd(cmds, ensure_unicode=False)\n  File \"C:\\Users\\\u738b\u4ed4\u6770\\AppData\\Local\\Programs\\Python\\Python36\\lib\\site-packages\\airtest\\core\\android\\adb.py\", line 187, in cmd\n    raise AdbError(stdout, stderr)\nairtest.core.error.AdbError: stdout[b''] stderr[b'/system/bin/sh: adb: not found\\r\\n']\n\nDuring handling of the above exception, another exception occurred:\n\nTraceback (most recent call last):\n  File \"C:\\Users\\\u738b\u4ed4\u6770\\AppData\\Local\\Programs\\Python\\Python36\\lib\\site-packages\\airtest\\utils\\logwraper.py\", line 72, in wrapper\n    res = f(*args, **kwargs)\n  File \"C:\\Users\\\u738b\u4ed4\u6770\\AppData\\Local\\Programs\\Python\\Python36\\lib\\site-packages\\airtest\\core\\api.py\", line 134, in shell\n    return G.DEVICE.shell(cmd)\n  File \"C:\\Users\\\u738b\u4ed4\u6770\\AppData\\Local\\Programs\\Python\\Python36\\lib\\site-packages\\airtest\\core\\android\\android.py\", line 257, in shell\n    return self.adb.shell(*args, **kwargs)\n  File \"C:\\Users\\\u738b\u4ed4\u6770\\AppData\\Local\\Programs\\Python\\Python36\\lib\\site-packages\\airtest\\core\\android\\adb.py\", line 370, in shell\n    raise AdbShellError(err.stdout, err.stderr)\nairtest.core.error.AdbShellError: stdout[b''] stderr[b'/system/bin/sh: adb: not found\\r\\n']\n", "end_time": 1604334225.353622}}
